Workbook

Sheet Dashboard CEO
A1: CCB MART — BẢNG ĐIỀU HÀNH CEO (V13.2.1)
A2: Dựa trên MasterDoc V13.2.1 — Mục 7.3, 7.4, 7.14 | Đơn vị: VNĐ nếu không ghi khác
A4: THAM SỐ ĐẦU VÀO
B5: Giá 1 combo (VNĐ) | C5: 2000000
B6: COGS blended (%) | C6: 0.4
B7: % doanh thu CCB Mart qua kênh CTV | C7: 0.6
B8: Chi phí vận hành khác (X-WISE, logistics, MKT, overhead...) | C8: 0.13
A10: 3 KỊCH BẢN HỆ THỐNG (tổ chức có 1 GĐKD)
B11: Chỉ tiêu | C11: TỐI THIỂU | D11: TIÊU CHUẨN | E11: MẠNH MẼ | F11: Ghi chú
B12: Số GĐKD | C12: 1 | D12: 1 | E12: 1 | F12: Mỗi tổ chức 1 GĐKD
B13: Số GĐV | C13: 2 | D13: 4 | E13: 6 | F13: Trực thuộc GĐKD
B14: Số TP | C14: 4 | D14: 8 | E14: 12 | F14: Trực thuộc GĐV (hoặc GĐKD)
B15: Số PP | C15: 8 | D15: 16 | E15: 24 | F15: Trực thuộc TP
B16: Số CTV | C16: 16 | D16: 32 | E16: 48 | F16: Trực thuộc PP
A18: Combo bán cá nhân/người/tháng (combo)
B19: Combo GĐKD | C19: 50 | D19: 50 | E19: 100
B20: Combo GĐV | C20: 50 | D20: 50 | E20: 100
B21: Combo TP | C21: 50 | D21: 50 | E21: 100
B22: Combo PP | C22: 50 | D22: 50 | E22: 100
B23: Combo CTV | C23: 10 | D23: 10 | E23: 30
A25: TỔNG HỢP
B26: Tổng headcount (người) | C26: =SUM(C12:C16) -> 31 | D26: =SUM(D12:D16) -> 61 | E26: =SUM(E12:E16) -> 91
B27: Tổng combo/tháng (combo) | C27: =C12*C19+C13*C20+C14*C21+C15*C22+C16*C23 -> 910 | D27: =D12*D19+D13*D20+D14*D21+D15*D22+D16*D23 -> 1770 | E27: =E12*E19+E13*E20+E14*E21+E15*E22+E16*E23 -> 5740
B28: Doanh thu hệ thống | C28: =C27*$C$5 -> 1820000000 | D28: =D27*$C$5 -> 3540000000 | E28: =E27*$C$5 -> 11480000000
B29: COGS (50% doanh thu) | C29: =C28*$C$6 -> 728000000 | D29: =D28*$C$6 -> 1416000000 | E29: =E28*$C$6 -> 4592000000
A31: CHI PHÍ KÊNH CTV (từ sheet Chi phí hệ thống)
B32: Tổng hoa hồng bán (HH) | C32: ='Chi phí hệ thống'!D24 -> 452000000 | D32: ='Chi phí hệ thống'!F24 -> 866000000 | E32: ='Chi phí hệ thống'!H24 -> 2752000000
B33: Tổng Thù lao DV duy trì | C33: ='Chi phí hệ thống'!D32 -> 146000000 | D33: ='Chi phí hệ thống'!F32 -> 262000000 | E33: ='Chi phí hệ thống'!H32 -> 378000000
B34: Tổng Phí QL nhóm F1+F2+F3 | C34: ='Chi phí hệ thống'!D44 -> 224000000 | D34: ='Chi phí hệ thống'!F44 -> 448000000 | E34: ='Chi phí hệ thống'!H44 -> 1.344e+09
B35: TỔNG CHI PHÍ KÊNH CTV | C35: =SUM(C32:C34) -> 822000000 | D35: =SUM(D32:D34) -> 1576000000 | E35: =SUM(E32:E34) -> 4474000000
B36: % / Doanh thu kênh CTV (chuẩn V13.2: ≤45%) | C36: =IFERROR(C35/C28,0) -> 0.45164835 | D36: =IFERROR(D35/D28,0) -> 0.44519774 | E36: =IFERROR(E35/E28,0) -> 0.38972125
A38: P&L TÍNH NHANH (kênh CTV)
B39: Doanh thu | C39: =C28 -> 1820000000 | D39: =D28 -> 3540000000 | E39: =E28 -> 11480000000
B40: (-) COGS 50% | C40: =-C29 -> -728000000 | D40: =-D29 -> -1416000000 | E40: =-E29 -> -4592000000
B41: (-) Chi phí kênh CTV (HH+TL+F) | C41: =-C35 -> -822000000 | D41: =-D35 -> -1576000000 | E41: =-E35 -> -4474000000
B42: (-) Vận hành khác (X-WISE+MKT+...) | C42: =-C28*$C$8 -> -236600000 | D42: =-D28*$C$8 -> -460200000 | E42: =-E28*$C$8 -> -1492400000
B43: EBITDA ước tính | C43: =SUM(C39:C42) -> 33400000 | D43: =SUM(D39:D42) -> 87800000 | E43: =SUM(E39:E42) -> 921600000
B44: EBITDA / Doanh thu (%) — mục tiêu 5-10% | C44: =IFERROR(C43/C39,0) -> 0.018351648 | D44: =IFERROR(D43/D39,0) -> 0.02480226 | E44: =IFERROR(E43/E39,0) -> 0.080278746
A46: CẢNH BÁO & KHUYẾN NGHỊ
B47: Nếu tổng chi phí kênh CTV vượt 45% doanh thu kênh → kích hoạt Soft Salary (Mục 7.8)
...

Sheet Công thức V13.2.1
A1: CÔNG THỨC V13.2.1 — CHƯƠNG 7
A3: 7.3. Bảng xếp hạng — Hoa hồng bán lẻ & Thù lao DV duy trì
A4: Xếp hạng | B4: % HH bán lẻ | C4: Thù lao DV duy trì (VNĐ/tháng) | D4: Điều kiện duy trì | E4: Ghi chú
A5: CTV | B5: 0.2 | C5: 0 | D5: Không bắt buộc doanh số | E5: Cá nhân, không phí gia nhập
A6: PP | B6: 0.2 | C6: 5000000 | D6: 50 combo/tháng | E6: Hộ KD
A7: TP | B7: 0.3 | C7: 10000000 | D7: 50cb + nhóm ≥150cb | E7: Hộ KD
A8: GĐV | B8: 0.35 | C8: 18000000 | D8: Duy trì ĐK, log 20h/tháng | E8: Hộ KD
A9: GĐKD | B9: 0.38 | C9: 30000000 | D9: 3 tháng → HĐLĐ | E9: HKD → HĐLĐ
A11: 7.4. Phí quản lý trong nhóm (Cấp 1 / 2 / 3)
A12: Loại phí | B12: Người thụ hưởng | C12: Tỷ lệ | D12: Tính trên | E12: Điều kiện
A13: Cấp 1 (F1) | B13: Cấp trên trực tiếp (TP trở lên) | C13: 0.1 | D13: Combo của cấp 1 | E13: 20h đào tạo/tháng + log hợp lệ
A14: Cấp 2 (F2) | B14: Cấp trên gián tiếp (GĐV trở lên) | C14: 0.05 | D14: Combo của cấp 2 | E14: 20h đào tạo/tháng + log hợp lệ
A15: Cấp 3 (F3) | B15: Cấp trên xa hơn (GĐKD) | C15: 0.03 | D15: Combo của cấp 3 | E15: 20h đào tạo/tháng + log hợp lệ
A17: Ví dụ 7.4: CTV E bán 100cb = 200tr
A18: → D (TP, cấp 1) nhận 10% × 200tr = 20tr; C (GĐV, cấp 2) nhận 5% = 10tr; B (GĐKD, cấp 3) nhận 3% = 6tr
A20: Ma trận: Ai nhận phí gì?
A21: Vai trò | B21: Nhận HH | C21: Nhận Thù lao | D21: Nhận F1/F2/F3 | E21: Điều kiện
A22: CTV | B22: Có (20%) | C22: Không | D22: Không | E22: Chỉ bán cá nhân
A23: PP | B23: Có (20%) | C23: 5tr | D23: KHÔNG nhận F | E23: PP không phải TP+
A24: TP | B24: Có (30%) | C24: 10tr | D24: F1 ✓, F2 ✓, F3 ✗ | E24: TP là TP+ và GĐV-
A25: GĐV | B25: Có (35%) | C25: 18tr | D25: F1 ✓, F2 ✓, F3 ✗ | E25: GĐV là GĐV+ nhưng không phải GĐKD
A26: GĐKD | B26: Có (38%) | C26: 30tr | D26: F1 ✓, F2 ✓, F3 ✓ | E26: GĐKD nhận đủ 3 cấp
A29: 7.8. Soft Salary (Điều tiết quỹ thù lao)
A30: Kích hoạt khi: Tổng quỹ Thù lao DV kênh CTV > 5% doanh thu kênh CTV/tháng
A31: Cơ chế: Giảm thù lao cố định, bù bằng thù lao điều chỉnh theo hiệu suất đội nhóm
A33: 7.9. Hệ số K (Điều tiết khi vượt ngân sách)
A34: Kích hoạt khi: F-fees + phí đào tạo > ~18-20% doanh thu
A35: Áp K vào TẤT CẢ khoản chi, K = 0.7 → 1.0

Sheet 3 Mô hình cây
A1: 3 MÔ HÌNH CÂY ĐIỂN HÌNH — 1 TỔ CHỨC (1 GĐKD)
A3: HEADCOUNT 3 KỊCH BẢN
B4: Vai trò | C4: Tối thiểu | D4: Tiêu chuẩn | E4: Mạnh mẽ | F4: Ghi chú
B5: GĐKD | C5: 1 | D5: 1 | E5: 1 | F5: Luôn 1 GĐKD/tổ chức
B6: GĐV (trực thuộc GĐKD) | C6: 2 | D6: 4 | E6: 6 | F6: Cấp 1 của GĐKD
B7: TP (trực thuộc GĐV) | C7: 4 | D7: 8 | E7: 12 | F7: Cấp 2 của GĐKD
B8: PP (trực thuộc TP) | C8: 8 | D8: 16 | E8: 24 | F8: Cấp 3 của GĐKD
B9: CTV (trực thuộc PP) | C9: 16 | D9: 32 | E9: 48 | F9: Cấp 4 — không sinh F cho GĐKD
B10: Tổng headcount | C10: =SUM(C5:C9) -> 31 | D10: =SUM(D5:D9) -> 61 | E10: =SUM(E5:E9) -> 91
B11: Combo/người/tháng (CTV=10-30, khác=50-100)
B12: Tổng combo/tháng (hệ thống) | C12: ='Dashboard CEO'!C27 -> 910 | D12: ='Dashboard CEO'!D27 -> 1770 | E12: ='Dashboard CEO'!E27 -> 5740
B13: Doanh thu hệ thống (VNĐ) | C13: ='Dashboard CEO'!C28 -> 1820000000 | D13: ='Dashboard CEO'!D28 -> 3540000000 | E13: ='Dashboard CEO'!E28 -> 11480000000
A15: SƠ ĐỒ CÂY (TIÊU CHUẨN)
A16: GĐKD (50cb)
A17: │
A18: ┌──────┬───────┴──────┬──────┐
A19: GĐV-1 GĐV-2 GĐV-3 GĐV-4 [4 GĐV × 50cb = 200cb cấp 1]
A20: │ │ │ │
A21: ┌─┴─┐ ┌─┴─┐ ┌─┴─┐ ┌─┴─┐
A22: TP-1..8 (2 TP/GĐV) [8 TP × 50cb = 400cb cấp 2]
A23: │
A24: ┌──┴──┐
A25: PP-1..16 (2 PP/TP) [16 PP × 50cb = 800cb cấp 3 — GĐKD nhận F3]
A26: │
A27: CTV-1..32 (2 CTV/PP) [32 CTV × 10cb = 320cb — cấp 4, GĐKD không nhận]

Sheet Thu nhập per role
A1: THU NHẬP MỘT NGƯỜI THEO VAI TRÒ & KỊCH BẢN
A3: Tham số combo/cấp (từ sơ đồ cây đã dựng)
B4: Chỉ tiêu / Vai trò | C4: Tối thiểu | D4: Tiêu chuẩn | E4: Mạnh mẽ | F4: Công thức / Ghi chú
A5: CẤP 1 — CTV (tự bán, không thù lao, không F)
B6: Combo cá nhân/tháng | C6: 10 | D6: 10 | E6: 30 | F6: Input (combo/CTV/tháng)
B7: HH bán (20%) | C7: =0.2*C6*'Dashboard CEO'!$C$5 -> 4000000 | D7: =0.2*D6*'Dashboard CEO'!$C$5 -> 4000000 | E7: =0.2*E6*'Dashboard CEO'!$C$5 -> 12000000 | F7: 20% × cb × giá
B8: TỔNG THU NHẬP CTV/THÁNG | C8: =C7 -> 4000000 | D8: =D7 -> 4000000 | E8: =E7 -> 12000000
A10: CẤP 2 — PP (HH + Thù lao; KHÔNG nhận F1/F2/F3)
B11: Combo cá nhân/tháng | C11: 50 | D11: 50 | E11: 100 | F11: Input
B12: HH bán (20%) | C12: =0.2*C11*'Dashboard CEO'!$C$5 -> 20000000 | D12: =0.2*D11*'Dashboard CEO'!$C$5 -> 20000000 | E12: =0.2*E11*'Dashboard CEO'!$C$5 -> 40000000 | F12: 20% × cb × giá
B13: Thù lao DV duy trì | C13: 5000000 | D13: 5000000 | E13: 5000000 | F13: Cố định 5tr (7.3)
B14: TỔNG THU NHẬP PP/THÁNG | C14: =C12+C13 -> 25000000 | D14: =D12+D13 -> 25000000 | E14: =E12+E13 -> 45000000
A16: CẤP 3 — TP (HH + Thù lao + F1 + F2; KHÔNG nhận F3)
B17: Combo cá nhân TP/tháng | C17: 50 | D17: 50 | E17: 100 | F17: Input
B18: Combo cấp 1 (PP trực thuộc + CTV direct) | C18: 100 | D18: 100 | E18: 200 | F18: Tổng cb do cấp 1 của TP bán
B19: Combo cấp 2 (CTV qua PP) | C19: 20 | D19: 40 | E19: 80 | F19: Tổng cb do cấp 2 của TP bán
B20: HH bán (30%) | C20: =0.3*C17*'Dashboard CEO'!$C$5 -> 30000000 | D20: =0.3*D17*'Dashboard CEO'!$C$5 -> 30000000 | E20: =0.3*E17*'Dashboard CEO'!$C$5 -> 60000000 | F20: 30% × cb cá nhân × giá
B21: Thù lao DV duy trì | C21: 10000000 | D21: 10000000 | E21: 10000000 | F21: Cố định 10tr (7.3)
B22: F1 (10% × cấp 1) | C22: =0.1*C18*'Dashboard CEO'!$C$5 -> 20000000 | D22: =0.1*D18*'Dashboard CEO'!$C$5 -> 20000000 | E22: =0.1*E18*'Dashboard CEO'!$C$5 -> 40000000 | F22: 10% × cb cấp 1 × giá
B23: F2 (5% × cấp 2) | C23: =0.05*C19*'Dashboard CEO'!$C$5 -> 2000000 | D23: =0.05*D19*'Dashboard CEO'!$C$5 -> 4000000 | E23: =0.05*E19*'Dashboard CEO'!$C$5 -> 8000000 | F23: 5% × cb cấp 2 × giá
B24: F3 | C24: 0 | D24: 0 | E24: 0 | F24: TP không phải GĐKD → không nhận
B25: TỔNG THU NHẬP TP/THÁNG | C25: =SUM(C20:C24) -> 62000000 | D25: =SUM(D20:D24) -> 64000000 | E25: =SUM(E20:E24) -> 118000000
A27: CẤP 4 — GĐV (HH + Thù lao + F1 + F2; KHÔNG nhận F3)
B28: Combo cá nhân GĐV/tháng | C28: 50 | D28: 50 | E28: 100 | F28: Input
B29: Combo cấp 1 (TP/PP direct dưới GĐV) | C29: 100 | D29: 150 | E29: 300
B30: Combo cấp 2 (PP/CTV dưới TP) | C30: 100 | D30: 150 | E30: 300
B31: HH bán (35%) | C31: =0.35*C28*'Dashboard CEO'!$C$5 -> 35000000 | D31: =0.35*D28*'Dashboard CEO'!$C$5 -> 35000000 | E31: =0.35*E28*'Dashboard CEO'!$C$5 -> 70000000
B32: Thù lao DV duy trì | C32: 18000000 | D32: 18000000 | E32: 18000000 | F32: Cố định 18tr (7.3 V13.2.1)
B33: F1 (10% × cấp 1) | C33: =0.1*C29*'Dashboard CEO'!$C$5 -> 20000000 | D33: =0.1*D29*'Dashboard CEO'!$C$5 -> 30000000 | E33: =0.1*E29*'Dashboard CEO'!$C$5 -> 60000000
B34: F2 (5% × cấp 2) | C34: =0.05*C30*'Dashboard CEO'!$C$5 -> 10000000 | D34: =0.05*D30*'Dashboard CEO'!$C$5 -> 15000000 | E34: =0.05*E30*'Dashboard CEO'!$C$5 -> 30000000
B35: F3 | C35: 0 | D35: 0 | E35: 0 | F35: GĐV không phải GĐKD → không nhận
B36: TỔNG THU NHẬP GĐV/THÁNG | C36: =SUM(C31:C35) -> 83000000 | D36: =SUM(D31:D35) -> 98000000 | E36: =SUM(E31:E35) -> 178000000
A38: CẤP 5 — GĐKD (HH + Thù lao + F1 + F2 + F3)
B39: Combo cá nhân GĐKD/tháng | C39: 50 | D39: 50 | E39: 100
B40: Combo cấp 1 (GĐV direct) | C40: 100 | D40: 200 | E40: 400
B41: Combo cấp 2 (TP qua GĐV) | C41: 200 | D41: 400 | E41: 600
B42: Combo cấp 3 (PP qua TP) | C42: 400 | D42: 800 | E42: 1200
B43: HH bán (38%) | C43: =0.38*C39*'Dashboard CEO'!$C$5 -> 38000000 | D43: =0.38*D39*'Dashboard CEO'!$C$5 -> 38000000 | E43: =0.38*E39*'Dashboard CEO'!$C$5 -> 76000000
B44: Thù lao DV duy trì | C44: 30000000 | D44: 30000000 | E44: 30000000 | F44: Cố định 30tr (7.3)
B45: F1 (10% × cấp 1) | C45: =0.1*C40*'Dashboard CEO'!$C$5 -> 20000000 | D45: =0.1*D40*'Dashboard CEO'!$C$5 -> 40000000 | E45: =0.1*E40*'Dashboard CEO'!$C$5 -> 80000000
...

Sheet Chi phí hệ thống
A1: TỔNG CHI PHÍ KÊNH CTV — 3 KỊCH BẢN
B3: Khoản mục | C3: Cách tính | D3: Tối thiểu | E3: % DT | F3: Tiêu chuẩn | G3: % DT | H3: Mạnh mẽ
A5: 1. HOA HỒNG BÁN LẺ
B6: HH CTV (20%) | C6: 20% × CTV_count × CTV_cb × price | D6: =0.2*'Dashboard CEO'!C16*'Dashboard CEO'!C23*'Dashboard CEO'!$C$5 -> 64000000 | E6: =D6/'Dashboard CEO'!C$28 -> 0.035164835 | F6: =0.2*'Dashboard CEO'!D16*'Dashboard CEO'!D23*'Dashboard CEO'!$C$5 -> 128000000 | G6: =F6/'Dashboard CEO'!D$28 -> 0.036158192 | H6: =0.2*'Dashboard CEO'!E16*'Dashboard CEO'!E23*'Dashboard CEO'!$C$5 -> 5.76e+08
B7: HH PP (20%) | C7: 20% × PP × PP_cb × price | D7: =0.2*'Dashboard CEO'!C15*'Dashboard CEO'!C22*'Dashboard CEO'!$C$5 -> 160000000 | E7: =D7/'Dashboard CEO'!C$28 -> 0.087912088 | F7: =0.2*'Dashboard CEO'!D15*'Dashboard CEO'!D22*'Dashboard CEO'!$C$5 -> 320000000 | G7: =F7/'Dashboard CEO'!D$28 -> 0.09039548 | H7: =0.2*'Dashboard CEO'!E15*'Dashboard CEO'!E22*'Dashboard CEO'!$C$5 -> 9.6e+08
B8: HH TP (30%) | C8: 30% × TP × TP_cb × price | D8: =0.3*'Dashboard CEO'!C14*'Dashboard CEO'!C21*'Dashboard CEO'!$C$5 -> 120000000 | E8: =D8/'Dashboard CEO'!C$28 -> 0.065934066 | F8: =0.3*'Dashboard CEO'!D14*'Dashboard CEO'!D21*'Dashboard CEO'!$C$5 -> 240000000 | G8: =F8/'Dashboard CEO'!D$28 -> 0.06779661 | H8: =0.3*'Dashboard CEO'!E14*'Dashboard CEO'!E21*'Dashboard CEO'!$C$5 -> 7.2e+08
B9: HH GĐV (35%) | C9: 35% × GĐV × GĐV_cb × price | D9: =0.35*'Dashboard CEO'!C13*'Dashboard CEO'!C20*'Dashboard CEO'!$C$5 -> 70000000 | E9: =D9/'Dashboard CEO'!C$28 -> 0.038461538 | F9: =0.35*'Dashboard CEO'!D13*'Dashboard CEO'!D20*'Dashboard CEO'!$C$5 -> 140000000 | G9: =F9/'Dashboard CEO'!D$28 -> 0.039548023 | H9: =0.35*'Dashboard CEO'!E13*'Dashboard CEO'!E20*'Dashboard CEO'!$C$5 -> 4.2e+08
B10: HH GĐKD (38%) | C10: 38% × 1 × GĐKD_cb × price | D10: =0.38*'Dashboard CEO'!C12*'Dashboard CEO'!C19*'Dashboard CEO'!$C$5 -> 38000000 | E10: =D10/'Dashboard CEO'!C$28 -> 0.020879121 | F10: =0.38*'Dashboard CEO'!D12*'Dashboard CEO'!D19*'Dashboard CEO'!$C$5 -> 38000000 | G10: =F10/'Dashboard CEO'!D$28 -> 0.010734463 | H10: =0.38*'Dashboard CEO'!E12*'Dashboard CEO'!E19*'Dashboard CEO'!$C$5 -> 76000000
B24: TỔNG HOA HỒNG BÁN | D24: =SUM(D6:D10) -> 452000000 | E24: =D24/'Dashboard CEO'!C28 -> 0.24835165 | F24: =SUM(F6:F10) -> 866000000 | G24: =F24/'Dashboard CEO'!D28 -> 0.24463277 | H24: =SUM(H6:H10) -> 2752000000
A26: 2. THÙ LAO DV DUY TRÌ
B27: Thù lao PP (5tr) | C27: 5tr × PP_count | D27: =5000000*'Dashboard CEO'!C15 -> 40000000 | E27: =D27/'Dashboard CEO'!C$28 -> 0.021978022 | F27: =5000000*'Dashboard CEO'!D15 -> 80000000 | G27: =F27/'Dashboard CEO'!D$28 -> 0.02259887 | H27: =5000000*'Dashboard CEO'!E15 -> 120000000
B28: Thù lao TP (10tr) | C28: 10tr × TP_count | D28: =10000000*'Dashboard CEO'!C14 -> 40000000 | E28: =D28/'Dashboard CEO'!C$28 -> 0.021978022 | F28: =10000000*'Dashboard CEO'!D14 -> 80000000 | G28: =F28/'Dashboard CEO'!D$28 -> 0.02259887 | H28: =10000000*'Dashboard CEO'!E14 -> 120000000
B29: Thù lao GĐV (18tr) | C29: 18tr × GĐV_count | D29: =18000000*'Dashboard CEO'!C13 -> 36000000 | E29: =D29/'Dashboard CEO'!C$28 -> 0.01978022 | F29: =18000000*'Dashboard CEO'!D13 -> 72000000 | G29: =F29/'Dashboard CEO'!D$28 -> 0.020338983 | H29: =18000000*'Dashboard CEO'!E13 -> 108000000
B30: Thù lao GĐKD (30tr) | C30: 30tr × GĐKD_count | D30: =30000000*'Dashboard CEO'!C12 -> 30000000 | E30: =D30/'Dashboard CEO'!C$28 -> 0.016483516 | F30: =30000000*'Dashboard CEO'!D12 -> 30000000 | G30: =F30/'Dashboard CEO'!D$28 -> 0.0084745763 | H30: =30000000*'Dashboard CEO'!E12 -> 30000000
B32: TỔNG THÙ LAO DV DUY TRÌ | D32: =SUM(D27:D30) -> 146000000 | E32: =D32/'Dashboard CEO'!C28 -> 0.08021978 | F32: =SUM(F27:F30) -> 262000000 | G32: =F32/'Dashboard CEO'!D28 -> 0.074011299 | H32: =SUM(H27:H30) -> 378000000
A34: 3. PHÍ QUẢN LÝ NHÓM (F1/F2/F3)
B35: F1 từ GĐV → GĐKD (10%) | C35: 10% × GĐV_count × GĐV_cb × price | D35: =0.1*'Dashboard CEO'!C13*'Dashboard CEO'!C20*'Dashboard CEO'!$C$5 -> 20000000 | E35: =D35/'Dashboard CEO'!C$28 -> 0.010989011 | F35: =0.1*'Dashboard CEO'!D13*'Dashboard CEO'!D20*'Dashboard CEO'!$C$5 -> 40000000 | G35: =F35/'Dashboard CEO'!D$28 -> 0.011299435 | H35: =0.1*'Dashboard CEO'!E13*'Dashboard CEO'!E20*'Dashboard CEO'!$C$5 -> 1.2e+08
B36: F1 từ TP → GĐV (10%) | C36: 10% × TP_count × TP_cb × price | D36: =0.1*'Dashboard CEO'!C14*'Dashboard CEO'!C21*'Dashboard CEO'!$C$5 -> 40000000 | E36: =D36/'Dashboard CEO'!C$28 -> 0.021978022 | F36: =0.1*'Dashboard CEO'!D14*'Dashboard CEO'!D21*'Dashboard CEO'!$C$5 -> 80000000 | G36: =F36/'Dashboard CEO'!D$28 -> 0.02259887 | H36: =0.1*'Dashboard CEO'!E14*'Dashboard CEO'!E21*'Dashboard CEO'!$C$5 -> 2.4e+08
B37: F1 từ PP → TP (10%) | C37: 10% × PP_count × PP_cb × price | D37: =0.1*'Dashboard CEO'!C15*'Dashboard CEO'!C22*'Dashboard CEO'!$C$5 -> 80000000 | E37: =D37/'Dashboard CEO'!C$28 -> 0.043956044 | F37: =0.1*'Dashboard CEO'!D15*'Dashboard CEO'!D22*'Dashboard CEO'!$C$5 -> 160000000 | G37: =F37/'Dashboard CEO'!D$28 -> 0.04519774 | H37: =0.1*'Dashboard CEO'!E15*'Dashboard CEO'!E22*'Dashboard CEO'!$C$5 -> 4.8e+08
B38: F2 từ TP → GĐKD (5%) | C38: 5% × TP_count × TP_cb × price | D38: =0.05*'Dashboard CEO'!C14*'Dashboard CEO'!C21*'Dashboard CEO'!$C$5 -> 20000000 | E38: =D38/'Dashboard CEO'!C$28 -> 0.010989011 | F38: =0.05*'Dashboard CEO'!D14*'Dashboard CEO'!D21*'Dashboard CEO'!$C$5 -> 40000000 | G38: =F38/'Dashboard CEO'!D$28 -> 0.011299435 | H38: =0.05*'Dashboard CEO'!E14*'Dashboard CEO'!E21*'Dashboard CEO'!$C$5 -> 1.2e+08
B39: F2 từ PP → GĐV (5%) | C39: 5% × PP_count × PP_cb × price | D39: =0.05*'Dashboard CEO'!C15*'Dashboard CEO'!C22*'Dashboard CEO'!$C$5 -> 40000000 | E39: =D39/'Dashboard CEO'!C$28 -> 0.021978022 | F39: =0.05*'Dashboard CEO'!D15*'Dashboard CEO'!D22*'Dashboard CEO'!$C$5 -> 80000000 | G39: =F39/'Dashboard CEO'!D$28 -> 0.02259887 | H39: =0.05*'Dashboard CEO'!E15*'Dashboard CEO'!E22*'Dashboard CEO'!$C$5 -> 2.4e+08
B40: F3 từ PP → GĐKD (3%) | C40: 3% × PP_count × PP_cb × price | D40: =0.03*'Dashboard CEO'!C15*'Dashboard CEO'!C22*'Dashboard CEO'!$C$5 -> 24000000 | E40: =D40/'Dashboard CEO'!C$28 -> 0.013186813 | F40: =0.03*'Dashboard CEO'!D15*'Dashboard CEO'!D22*'Dashboard CEO'!$C$5 -> 48000000 | G40: =F40/'Dashboard CEO'!D$28 -> 0.013559322 | H40: =0.03*'Dashboard CEO'!E15*'Dashboard CEO'!E22*'Dashboard CEO'!$C$5 -> 144000000
B41: Từ CTV: 0 (PP không nhận F → F1 mất, chuỗi đứt) | C41: 0 — theo quy tắc 7.4 | D41: 0 | F41: 0 | H41: 0
B44: TỔNG PHÍ F1+F2+F3 | D44: =SUM(D35:D41) -> 224000000 | E44: =D44/'Dashboard CEO'!C28 -> 0.12307692 | F44: =SUM(F35:F41) -> 448000000 | G44: =F44/'Dashboard CEO'!D28 -> 0.12655367 | H44: =SUM(H35:H41) -> 1.344e+09
A46: TỔNG CHI PHÍ KÊNH CTV
B47: HH + Thù lao + F1+F2+F3 | D47: =D24+D32+D44 -> 822000000 | E47: =D47/'Dashboard CEO'!C28 -> 0.45164835 | F47: =F24+F32+F44 -> 1576000000 | G47: =F47/'Dashboard CEO'!D28 -> 0.44519774 | H47: =H24+H32+H44 -> 4474000000
